{
    "id": "dbpedia_6722_0",
    "rank": 87,
    "data": {
        "url": "https://forums.veeam.com/veeam-backup-replication-f2/socket-has-been-forcibly-closed-t46532.html",
        "read_more_link": "",
        "language": "en",
        "title": "Socket has been forcibly closed",
        "top_image": "https://img.veeam.com/seo/og/veeam.png",
        "meta_img": "https://img.veeam.com/seo/og/veeam.png",
        "images": [],
        "movies": [],
        "keywords": [],
        "meta_keywords": [
            ""
        ],
        "tags": null,
        "authors": [
            "nitramd » this post",
            "foggy » this post"
        ],
        "publish_date": "2017-11-03T02:16:49+00:00",
        "summary": "",
        "meta_description": "Veeam Community discussions and solutions for: Socket has been forcibly closed of Veeam Backup & Replication",
        "meta_lang": "en",
        "meta_favicon": "//img.veeam.com/favicon/favicon-16x16.ico",
        "meta_site_name": "Veeam Community Forums",
        "canonical_link": "https://forums.veeam.com/veeam-backup-replication-f2/socket-has-been-forcibly-closed-t46532.html",
        "text": "Code: Select all\n\n[08.11.2017 15:33:19] <01> Info [RemoteBackupTaskBuilder] Skipping VM XYZ-DC1 processing: completed [08.11.2017 15:33:20] <01> Info [NewRemoteOibAction] About to process source Oib (id='dd3539d0-564f-4b92-8f22-59b8dde294c2', CreationTime='11/7/2017 10:33:29 PM', Point='\\\\XYZ-SYN-001\\Veeam\\Backup of Host1\\Backup of Host1D2017-11-07T220047.vbk') into the target storage: '50879984-6da7-441e-9bf5-f1436b3e090b' [08.11.2017 15:33:20] <01> Info [ViTaskBuilder] Found source Oib (Storage: '\\\\XYZ-SYN-001\\Veeam\\Backup of Host1\\Backup of Host1D2017-11-07T220047.vbk', CreationTime: '11/7/2017 10:33:29 PM') for VM 'XYZ-Print' [08.11.2017 15:33:20] <01> Info Task total size: 60.0 GB [08.11.2017 15:33:20] <01> Info Task progress: '0%', '0' of '64,424,509,440' bytes, object '0' of '0' [08.11.2017 15:33:20] <01> Info Task total size: 60.0 GB [08.11.2017 15:33:20] <01> Info Task progress: '0%', '0' of '64,424,509,440' bytes, object '0' of '0' [08.11.2017 15:33:20] <01> Info [RemoteBackupTaskBuilder] Preparing new task for execution. XYZ-Print [08.11.2017 15:33:20] <01> Info [IdleStateVmController] Stopping idle [08.11.2017 15:33:20] <01> Info [TaskExecutor] Preparing task XYZ-Print [08.11.2017 15:33:20] <01> Info [TaskRepositoryResourceHelper] Adding target repository resource request to task XYZ-Print [08.11.2017 15:33:20] <01> Info [Id: 1db0ba92-3466-4569-990a-d034a75679c9, Type: vbk, State: Existing, IsSlotNeeded: True, Access: Read, ObjectId: <no object id>] [08.11.2017 15:33:20] <01> Info [TaskRepositoryResourceHelper] Adding source repository resource request to task XYZ-Print [08.11.2017 15:33:20] <01> Info [Id: 1db0ba92-3466-4569-990a-d034a75679c9, Type: vbk, State: Existing, IsSlotNeeded: True, Access: Read, ObjectId: <no object id>] [08.11.2017 15:33:20] <01> Info [TaskRepositoryResourceHelper] Adding file sessions resource request for 43 files to task XYZ-Print [08.11.2017 15:33:20] <01> Info Job size: 16.8 GB (16.8 GB provisioned). [08.11.2017 15:33:20] <01> Info [TaskExecutor] Task XYZ-Print prepared [08.11.2017 15:33:20] <01> Info [ParallelTaskExecutor] Starting task XYZ-Print execution [08.11.2017 15:33:20] <01> Info Waiting for backup infrastructure resources availability [08.11.2017 15:33:28] <07> Info [BackupMetaUpdater] Generating backup meta because it was requested by the following threads: [08.11.2017 15:33:28] <07> Info [BackupMetaUpdater] Thread <24> CPL-DSM [08.11.2017 15:33:28] <07> Error [JobSession] LastUserCryptoSpec is null. Cannot find the user key by the last storage. [08.11.2017 15:33:28] <07> Info Created mutex [Global\\BackupMeta[0e5a6d41-f687-43d8-ad41-ea05f214fbbe]] [08.11.2017 15:33:28] <07> Info Acquired mutex [Global\\BackupMeta[0e5a6d41-f687-43d8-ad41-ea05f214fbbe]] [08.11.2017 15:33:28] <07> Info [IncrementalMetaGenerator] Generating meta for backup [88a5f8f3-7411-4a96-820d-fbde0cb7680a], usn [2342835] [08.11.2017 15:33:28] <07> Info [BackupMeta] Saving backup meta to '|media|backups|seed|Seed job for COLO.vbm' [08.11.2017 15:33:28] <07> Info [Ssh] Check existing '/media/backups/seed' [08.11.2017 15:33:28] <07> Info [Ssh] Saving binary to '/media/backups/seed/Seed job for COLO.vbm_4_tmp'. [08.11.2017 15:33:29] <07> Info [Ssh] Check existing '/media/backups/seed/Seed job for COLO.vbm' [08.11.2017 15:33:29] <07> Info [Ssh] Check existing '/media/backups/seed/Seed job for COLO.vbm' [08.11.2017 15:33:29] <07> Info [Ssh] Deleting \"/media/backups/seed/Seed job for COLO.vbm\" [08.11.2017 15:33:29] <07> Info [Ssh] Check existing '/media/backups/seed/Seed job for COLO.vbm_4_tmp' [08.11.2017 15:33:29] <07> Info [Backup] SetMetaUpdateTimeAndVersion, old value: [11/8/2017 3:33:13 PM,3021] new value: [11/8/2017 3:33:29 PM,3022] [08.11.2017 15:33:29] <07> Info Releasing mutex [Global\\BackupMeta[0e5a6d41-f687-43d8-ad41-ea05f214fbbe]] [08.11.2017 15:33:29] <07> Info [BackupMetaUpdater] Backup meta generated [08.11.2017 15:33:43] <40> Info [AP] (3202) command: 'Invoke: Network.UpdateThrottling\\n{\\n (EInt32) KbpsWriteBandwidth = 5760\\n}\\n' [08.11.2017 15:33:43] <29> Info [AP] (3202) output: <VCPCommandResult result=\"true\" exception=\"\" /> [08.11.2017 15:33:43] <31> Info [AP] (3202) output: <VCPCommandArgs /> [08.11.2017 15:33:43] <31> Info [AP] (3202) output: > [08.11.2017 15:39:46] <15> Error (SSH Transport) error: ChannelError: An existing connection was forcibly closed by the remote host [08.11.2017 15:39:46] <15> Error [AP] (Client) error: An existing connection was forcibly closed by the remote host [08.11.2017 15:39:46] <15> Error (Client) error: ChannelError: An existing connection was forcibly closed by the remote hostAn existing connection was forcibly closed by the remote hostChannelError: An existing connection was forcibly closed by the remote host [08.11.2017 15:39:47] <48> Error [ReconnectableSocket][PacketAsyncReceiver] Exception on [b93e3bab-647e-4d36-8a0c-f3b6aae7eb29]. [08.11.2017 15:39:47] <48> Error Unexpected socket shutdown. (System.Exception) [08.11.2017 15:39:47] <48> Error at Veeam.Backup.Common.Reconnect.CPacketAsyncReceiver.PushData(CSocketAsyncEventArgsEx e) [08.11.2017 15:39:47] <48> Info [ReconnectableSocket] Nonretryable error on [b93e3bab-647e-4d36-8a0c-f3b6aae7eb29]. [08.11.2017 15:39:47] <48> Info [ReconnectableSocket] Reconnecting [b93e3bab-647e-4d36-8a0c-f3b6aae7eb29] (shutdown notification)... [08.11.2017 15:39:47] <48> Info [NetSocket] Connect [08.11.2017 15:39:47] <44> Error [ReconnectableSocket][PacketAsyncReceiver] Exception on [aac8507e-72bf-4412-9d64-3e490eaa53f7]. [08.11.2017 15:39:47] <44> Error Unexpected socket shutdown. (System.Exception) [08.11.2017 15:39:47] <44> Error at Veeam.Backup.Common.Reconnect.CPacketAsyncReceiver.PushData(CSocketAsyncEventArgsEx e) [08.11.2017 15:39:47] <44> Info [ReconnectableSocket] Nonretryable error on [aac8507e-72bf-4412-9d64-3e490eaa53f7]. [08.11.2017 15:39:47] <44> Info [ReconnectableSocket] Reconnecting [aac8507e-72bf-4412-9d64-3e490eaa53f7] (shutdown notification)... [08.11.2017 15:39:47] <44> Info [NetSocket] Connect [08.11.2017 15:39:48] <48> Error Failed to connect to agent's endpoint '192.168.5.21:2500'. Host: '192.168.5.21'. [08.11.2017 15:39:48] <48> Error No connection could be made because the target machine actively refused it 192.168.5.21:2500 (System.Net.Sockets.SocketException) [08.11.2017 15:39:48] <48> Error at System.Net.Sockets.Socket.DoConnect(EndPoint endPointSnapshot, SocketAddress socketAddress) [08.11.2017 15:39:48] <48> Error at System.Net.Sockets.Socket.Connect(EndPoint remoteEP) [08.11.2017 15:39:48] <48> Error at Veeam.Backup.Common.CNetSocket.Connect(IPEndPoint remoteEp) [08.11.2017 15:39:48] <48> Error at Veeam.Backup.AgentProvider.CAgentEndpointConnecter.ConnectToAgentEndpoint(ISocket socket, IAgentEndPoint endPoint) [08.11.2017 15:39:48] <44> Error Failed to connect to agent's endpoint '192.168.5.21:2500'. Host: '192.168.5.21'. [08.11.2017 15:39:48] <44> Error No connection could be made because the target machine actively refused it 192.168.5.21:2500 (System.Net.Sockets.SocketException) [08.11.2017 15:39:48] <44> Error at System.Net.Sockets.Socket.DoConnect(EndPoint endPointSnapshot, SocketAddress socketAddress) [08.11.2017 15:39:48] <44> Error at System.Net.Sockets.Socket.Connect(EndPoint remoteEP) [08.11.2017 15:39:48] <44> Error at Veeam.Backup.Common.CNetSocket.Connect(IPEndPoint remoteEp) [08.11.2017 15:39:48] <44> Error at Veeam.Backup.AgentProvider.CAgentEndpointConnecter.ConnectToAgentEndpoint(ISocket socket, IAgentEndPoint endPoint) [08.11.2017 15:39:49] <44> Warning [ReconnectableSocket] Failed to recover [aac8507e-72bf-4412-9d64-3e490eaa53f7]. [08.11.2017 15:39:49] <44> Error Reconnect operation was aborted. (Veeam.Backup.Common.CRegeneratedTraceException) [08.11.2017 15:39:49] <44> Error at Veeam.Backup.Common.CExceptionUtil.RegenTraceExc(Exception originalExc, String formatString, Object[] args) [08.11.2017 15:39:49] <44> Error at Veeam.Backup.Common.Reconnect.CNetworkReconnectContext.WaitOnRetry(TimeSpan interval, Exception firstChanceEx) [08.11.2017 15:39:49] <44> Error at Veeam.Backup.Common.Reconnect.CReconnectEngine.RunConnectCycle() [08.11.2017 15:39:49] <44> Error at Veeam.Backup.Common.Reconnect.CReconnectEngine.DoReconnect() [08.11.2017 15:39:49] <44> Error at Veeam.Backup.Common.Reconnect.CReconnectEngine.PerformReconnectSafe() [08.11.2017 15:39:49] <44> Error No connection could be made because the target machine actively refused it 192.168.5.21:2500 (System.Net.Sockets.SocketException) [08.11.2017 15:39:49] <44> Error at Veeam.Backup.AgentProvider.CAgentEndpointConnecter.ConnectToAgentEndpoint(ISocket socket, IAgentEndPoint endPoint) [08.11.2017 15:39:49] <44> Error at Veeam.Backup.AgentProvider.CAgentEndpointConnecter.Connect(IPEndPoint& connectedEndpoint) [08.11.2017 15:39:49] <44> Error at Veeam.Backup.AgentProvider.CReconnectableSessionStarter.Reconnect(CAgentEndpointConnecter connecter, Boolean redirectOutput) [08.11.2017 15:39:49] <44> Error at Veeam.Backup.Common.Reconnect.CReconnectEngine.RunConnectCycle() [08.11.2017 15:39:49] <48> Warning [ReconnectableSocket] Failed to recover [b93e3bab-647e-4d36-8a0c-f3b6aae7eb29]. [08.11.2017 15:39:49] <44> Error Reconnect operation was aborted. (Veeam.Backup.Common.CRegeneratedTraceException) [08.11.2017 15:39:49] <44> Error at Veeam.Backup.Common.CExceptionUtil.RegenTraceExc(Exception originalExc, String formatString, Object[] args) [08.11.2017 15:39:49] <44> Error at Veeam.Backup.Common.Reconnect.CErrorPort.TryRegenExc(Exception ex) [08.11.2017 15:39:49] <44> Error at Veeam.Backup.Common.Reconnect.CInterlockedReconnectEngine.UnlockAfterAccess() [08.11.2017 15:39:49] <44> Error at Veeam.Backup.Common.Reconnect.CPacketAsyncReceiver.PushData(CSocketAsyncEventArgsEx e) [08.11.2017 15:39:49] <44> Error at Veeam.Backup.Common.Reconnect.CPacketAsyncReceiver.OnRawDataReceived(Object sender, CSocketAsyncEventArgsEx e) [08.11.2017 15:39:49] <44> Error Unexpected socket shutdown. (System.Exception) [08.11.2017 15:39:49] <44> Error at Veeam.Backup.Common.Reconnect.CPacketAsyncReceiver.PushData(CSocketAsyncEventArgsEx e) [08.11.2017 15:39:49] <48> Error Reconnect operation was aborted. (Veeam.Backup.Common.CRegeneratedTraceException) [08.11.2017 15:39:49] <48> Error at Veeam.Backup.Common.CExceptionUtil.RegenTraceExc(Exception originalExc, String formatString, Object[] args) [08.11.2017 15:39:49] <48> Error at Veeam.Backup.Common.Reconnect.CNetworkReconnectContext.WaitOnRetry(TimeSpan interval, Exception firstChanceEx) [08.11.2017 15:39:49] <48> Error at Veeam.Backup.Common.Reconnect.CReconnectEngine.RunConnectCycle() [08.11.2017 15:39:49] <48> Error at Veeam.Backup.Common.Reconnect.CReconnectEngine.DoReconnect() [08.11.2017 15:39:49] <48> Error at Veeam.Backup.Common.Reconnect.CReconnectEngine.PerformReconnectSafe() [08.11.2017 15:39:49] <48> Error No connection could be made because the target machine actively refused it 192.168.5.21:2500 (System.Net.Sockets.SocketException) [08.11.2017 15:39:49] <48> Error at Veeam.Backup.AgentProvider.CAgentEndpointConnecter.ConnectToAgentEndpoint(ISocket socket, IAgentEndPoint endPoint) [08.11.2017 15:39:49] <48> Error at Veeam.Backup.AgentProvider.CAgentEndpointConnecter.Connect(IPEndPoint& connectedEndpoint) [08.11.2017 15:39:49] <48> Error at Veeam.Backup.AgentProvider.CReconnectableSessionStarter.Reconnect(CAgentEndpointConnecter connecter, Boolean redirectOutput) [08.11.2017 15:39:49] <48> Error at Veeam.Backup.Common.Reconnect.CReconnectEngine.RunConnectCycle() [08.11.2017 15:39:49] <48> Error Reconnect operation was aborted. (Veeam.Backup.Common.CRegeneratedTraceException) [08.11.2017 15:39:49] <48> Error at Veeam.Backup.Common.CExceptionUtil.RegenTraceExc(Exception originalExc, String formatString, Object[] args) [08.11.2017 15:39:49] <48> Error at Veeam.Backup.Common.Reconnect.CErrorPort.TryRegenExc(Exception ex) [08.11.2017 15:39:49] <48> Error at Veeam.Backup.Common.Reconnect.CInterlockedReconnectEngine.UnlockAfterAccess() [08.11.2017 15:39:49] <48> Error at Veeam.Backup.Common.Reconnect.CPacketAsyncReceiver.PushData(CSocketAsyncEventArgsEx e) [08.11.2017 15:39:49] <48> Error at Veeam.Backup.Common.Reconnect.CPacketAsyncReceiver.OnRawDataReceived(Object sender, CSocketAsyncEventArgsEx e) [08.11.2017 15:39:49] <48> Error Unexpected socket shutdown. (System.Exception) [08.11.2017 15:39:49] <48> Error at Veeam.Backup.Common.Reconnect.CPacketAsyncReceiver.PushData(CSocketAsyncEventArgsEx e) [08.11.2017 15:39:49] <15> Info [AP] (1309) state: closed"
    }
}