{
    "id": "wrong_mix_property_subsidiary_00048_2",
    "rank": 48,
    "data": {
        "url": "https://github.com/jupyter/notebook/issues/4079",
        "read_more_link": "",
        "language": "en",
        "title": "Kernal Error - FileNotFoundError: [WinError 2] The system cannot find the file specified · Issue #4079 · jupyter/notebook",
        "top_image": "https://opengraph.githubassets.com/8df2761a225e6136b5197bc784a372bc9f134bc9ad528a49b586de047c280206/jupyter/notebook/issues/4079",
        "meta_img": "https://opengraph.githubassets.com/8df2761a225e6136b5197bc784a372bc9f134bc9ad528a49b586de047c280206/jupyter/notebook/issues/4079",
        "images": [
            "https://avatars.githubusercontent.com/u/34067903?s=80&u=aa3898c21718264cafda499d81408e98c546cd66&v=4",
            "https://avatars.githubusercontent.com/u/29601590?s=80&u=a5ff38efe17b43e673de970802dffc279a6662da&v=4",
            "https://avatars.githubusercontent.com/u/29601590?s=80&u=a5ff38efe17b43e673de970802dffc279a6662da&v=4",
            "https://avatars.githubusercontent.com/u/29601590?s=40&u=a5ff38efe17b43e673de970802dffc279a6662da&v=4",
            "https://avatars.githubusercontent.com/u/34067903?s=80&u=aa3898c21718264cafda499d81408e98c546cd66&v=4",
            "https://avatars.githubusercontent.com/u/4471859?s=80&u=972478287ae6eca3fa78d3d0f4463a29075ccb09&v=4",
            "https://avatars.githubusercontent.com/u/34067903?s=80&u=aa3898c21718264cafda499d81408e98c546cd66&v=4",
            "https://avatars.githubusercontent.com/u/34067903?s=40&u=aa3898c21718264cafda499d81408e98c546cd66&v=4",
            "https://avatars.githubusercontent.com/u/3419955?s=80&u=d8e20853145498700ca2e0521dadabc93ee868f2&v=4",
            "https://avatars.githubusercontent.com/u/1411854?s=80&u=30c8d0f4c988136f24c2aa84bca26c554d51bb33&v=4",
            "https://avatars.githubusercontent.com/u/12793783?s=80&u=ca3301f9ebf446f5978ff17351a0a43224425420&v=4",
            "https://avatars.githubusercontent.com/u/5477995?s=80&v=4",
            "https://avatars.githubusercontent.com/u/6897398?s=80&u=f7ba9134f85efc4b84d682ad0109d791cfeed476&v=4",
            "https://avatars.githubusercontent.com/u/7261199?s=80&u=319b894a1bd1558548a3d58360bb354e6314ffad&v=4",
            "https://avatars.githubusercontent.com/u/3989299?s=80&u=c2e0edeb0e4ac9a37d2f671494ed1b2d20f75fa3&v=4",
            "https://avatars.githubusercontent.com/u/3770323?s=40&v=4",
            "https://avatars.githubusercontent.com/u/24991855?s=40&v=4",
            "https://avatars.githubusercontent.com/u/22682999?s=40&v=4",
            "https://avatars.githubusercontent.com/u/2090236?s=40&v=4",
            "https://avatars.githubusercontent.com/u/18582718?s=80&u=3213519b5e178d90a9506d407298771f80b0e7e3&v=4",
            "https://avatars.githubusercontent.com/u/8553049?s=80&u=a61f74343c8095e0f2ed7caddb603255cfc7b457&v=4",
            "https://avatars.githubusercontent.com/u/27565752?s=80&u=784456c12c63599f0b9cf30cfe27697aa54dd20a&v=4",
            "https://avatars.githubusercontent.com/u/49893001?s=80&u=6c357a510e298a112243284f91ddfd209344f25e&v=4",
            "https://avatars.githubusercontent.com/u/43821429?s=80&u=9dc66e855f3c1df046b56fcdd27b39c80cdaaccc&v=4",
            "https://avatars.githubusercontent.com/u/9156129?s=80&u=33b1ffa11f91b9b1bb0b88add8f91ce1db816212&v=4",
            "https://avatars.githubusercontent.com/u/55522031?s=80&v=4",
            "https://avatars.githubusercontent.com/u/75523975?s=80&v=4",
            "https://avatars.githubusercontent.com/u/3274?s=80&u=6c178057fd80ad33925ef624bfe64ba07cc624c5&v=4",
            "https://avatars.githubusercontent.com/u/36908423?s=80&u=c36c78c10a08332d22a3cf6e07595eb218f1ae1c&v=4",
            "https://avatars.githubusercontent.com/u/7661092?s=80&u=3f0df78290062680842109cf980cce0573c511b1&v=4",
            "https://avatars.githubusercontent.com/u/58980785?s=80&u=a69e475e04dc6e6bf2ba541fb6a503edf5f743e5&v=4",
            "https://avatars.githubusercontent.com/u/35448482?s=80&v=4",
            "https://avatars.githubusercontent.com/u/55556907?s=80&u=00cb3f045589339c871888550fb6b0968982fa41&v=4",
            "https://avatars.githubusercontent.com/u/46515616?s=80&u=4bedd5f7ad7deed218af3133fd8bdedaf15c62e6&v=4",
            "https://avatars.githubusercontent.com/u/72651092?s=80&u=17b03ebe87f04032ae16b3632003089a4efa7942&v=4",
            "https://user-images.githubusercontent.com/72651092/122754024-0e4dae80-d2ce-11eb-9301-e36a41504fbe.png",
            "https://avatars.githubusercontent.com/u/72651092?s=80&u=17b03ebe87f04032ae16b3632003089a4efa7942&v=4",
            "https://avatars.githubusercontent.com/u/72651092?s=80&u=17b03ebe87f04032ae16b3632003089a4efa7942&v=4",
            "https://avatars.githubusercontent.com/u/72651092?s=80&u=17b03ebe87f04032ae16b3632003089a4efa7942&v=4",
            "https://avatars.githubusercontent.com/u/22599560?s=80&u=f47845acdac9fecf5ddb282e1df84cfaab10c084&v=4",
            "https://avatars.githubusercontent.com/u/72651092?s=80&u=17b03ebe87f04032ae16b3632003089a4efa7942&v=4",
            "https://avatars.githubusercontent.com/u/22599560?s=40&u=f47845acdac9fecf5ddb282e1df84cfaab10c084&v=4",
            "https://avatars.githubusercontent.com/u/41713590?s=80&v=4",
            "https://avatars.githubusercontent.com/u/44419338?s=80&u=29a75ed1572f762421da4d8a4c88d7a666131a5a&v=4",
            "https://avatars.githubusercontent.com/u/28824228?s=80&u=2ce2dd94dae00fa8f21683f3b1b827f24381baff&v=4",
            "https://avatars.githubusercontent.com/in/15368?s=40&v=4",
            "https://avatars.githubusercontent.com/in/15368?s=40&v=4",
            "https://avatars.githubusercontent.com/u/3274?s=52&v=4",
            "https://avatars.githubusercontent.com/u/1411854?s=52&v=4",
            "https://avatars.githubusercontent.com/u/3419955?s=52&v=4",
            "https://avatars.githubusercontent.com/u/3989299?s=52&v=4",
            "https://avatars.githubusercontent.com/u/4471859?s=52&v=4",
            "https://avatars.githubusercontent.com/u/5477995?s=52&v=4",
            "https://avatars.githubusercontent.com/u/6897398?s=52&v=4",
            "https://avatars.githubusercontent.com/u/7261199?s=52&v=4",
            "https://avatars.githubusercontent.com/u/7661092?s=52&v=4",
            "https://avatars.githubusercontent.com/u/8553049?s=52&v=4",
            "https://avatars.githubusercontent.com/u/9156129?s=52&v=4",
            "https://avatars.githubusercontent.com/u/12793783?s=52&v=4",
            "https://avatars.githubusercontent.com/u/18582718?s=52&v=4",
            "https://avatars.githubusercontent.com/u/22599560?s=52&v=4",
            "https://avatars.githubusercontent.com/u/27565752?s=52&v=4",
            "https://avatars.githubusercontent.com/u/28824228?s=52&v=4",
            "https://avatars.githubusercontent.com/u/29601590?s=52&v=4",
            "https://avatars.githubusercontent.com/u/34067903?s=52&v=4",
            "https://avatars.githubusercontent.com/u/35448482?s=52&v=4",
            "https://avatars.githubusercontent.com/u/36908423?s=52&v=4"
        ],
        "movies": [],
        "keywords": [],
        "meta_keywords": [
            ""
        ],
        "tags": null,
        "authors": [],
        "publish_date": null,
        "summary": "",
        "meta_description": "When I create a new env in Anaconda: conda create -n envname python=3.6 Then I install jupyter notebook: conda install jupyter notebook When I start the jupyter notebook and create a new python3 I get the following Error: Traceback (most...",
        "meta_lang": "en",
        "meta_favicon": "https://github.com/fluidicon.png",
        "meta_site_name": "GitHub",
        "canonical_link": "https://github.com/jupyter/notebook/issues/4079",
        "text": "Traceback (most recent call last): File \"E:\\Jupyter\\miniconda3\\envs\\axat\\lib\\site-packages\\tornado\\web.py\", line 1703, in _execute result = await result File \"E:\\Jupyter\\miniconda3\\envs\\axat\\lib\\site-packages\\tornado\\gen.py\", line 742, in run yielded = self.gen.throw(*exc_info) # type: ignore File \"E:\\Jupyter\\miniconda3\\envs\\axat\\lib\\site-packages\\notebook\\services\\sessions\\handlers.py\", line 73, in post type=mtype)) File \"E:\\Jupyter\\miniconda3\\envs\\axat\\lib\\site-packages\\tornado\\gen.py\", line 735, in run value = future.result() File \"E:\\Jupyter\\miniconda3\\envs\\axat\\lib\\site-packages\\tornado\\gen.py\", line 742, in run yielded = self.gen.throw(*exc_info) # type: ignore File \"E:\\Jupyter\\miniconda3\\envs\\axat\\lib\\site-packages\\notebook\\services\\sessions\\sessionmanager.py\", line 79, in create_session kernel_id = yield self.start_kernel_for_session(session_id, path, name, type, kernel_name) File \"E:\\Jupyter\\miniconda3\\envs\\axat\\lib\\site-packages\\tornado\\gen.py\", line 735, in run value = future.result() File \"E:\\Jupyter\\miniconda3\\envs\\axat\\lib\\site-packages\\tornado\\gen.py\", line 742, in run yielded = self.gen.throw(*exc_info) # type: ignore File \"E:\\Jupyter\\miniconda3\\envs\\axat\\lib\\site-packages\\notebook\\services\\sessions\\sessionmanager.py\", line 92, in start_kernel_for_session self.kernel_manager.start_kernel(path=kernel_path, kernel_name=kernel_name) File \"E:\\Jupyter\\miniconda3\\envs\\axat\\lib\\site-packages\\tornado\\gen.py\", line 735, in run value = future.result() File \"E:\\Jupyter\\miniconda3\\envs\\axat\\lib\\site-packages\\tornado\\gen.py\", line 209, in wrapper yielded = next(result) File \"E:\\Jupyter\\miniconda3\\envs\\axat\\lib\\site-packages\\notebook\\services\\kernels\\kernelmanager.py\", line 160, in start_kernel super(MappingKernelManager, self).start_kernel(**kwargs) File \"E:\\Jupyter\\miniconda3\\envs\\axat\\lib\\site-packages\\jupyter_client\\multikernelmanager.py\", line 110, in start_kernel km.start_kernel(**kwargs) File \"E:\\Jupyter\\miniconda3\\envs\\axat\\lib\\site-packages\\jupyter_client\\manager.py\", line 246, in start_kernel kernel_cmd = self.format_kernel_cmd(extra_arguments=extra_arguments) File \"E:\\Jupyter\\miniconda3\\envs\\axat\\lib\\site-packages\\jupyter_client\\manager.py\", line 170, in format_kernel_cmd cmd = self.kernel_spec.argv + extra_arguments File \"E:\\Jupyter\\miniconda3\\envs\\axat\\lib\\site-packages\\jupyter_client\\manager.py\", line 82, in kernel_spec self._kernel_spec = self.kernel_spec_manager.get_kernel_spec(self.kernel_name) File \"E:\\Jupyter\\miniconda3\\envs\\axat\\lib\\site-packages\\jupyter_client\\kernelspec.py\", line 238, in get_kernel_spec return self._get_kernel_spec_by_name(kernel_name, resource_dir) File \"E:\\Jupyter\\miniconda3\\envs\\axat\\lib\\site-packages\\jupyter_client\\kernelspec.py\", line 201, in _get_kernel_spec_by_name return self.kernel_spec_class.from_resource_dir(resource_dir) File \"E:\\Jupyter\\miniconda3\\envs\\axat\\lib\\site-packages\\jupyter_client\\kernelspec.py\", line 47, in from_resource_dir kernel_dict = json.load(f) File \"E:\\Jupyter\\miniconda3\\envs\\axat\\lib\\json\\__init__.py\", line 296, in load parse_constant=parse_constant, object_pairs_hook=object_pairs_hook, **kw) File \"E:\\Jupyter\\miniconda3\\envs\\axat\\lib\\json\\__init__.py\", line 348, in loads return _default_decoder.decode(s) File \"E:\\Jupyter\\miniconda3\\envs\\axat\\lib\\json\\decoder.py\", line 337, in decode obj, end = self.raw_decode(s, idx=_w(s, 0).end()) File \"E:\\Jupyter\\miniconda3\\envs\\axat\\lib\\json\\decoder.py\", line 355, in raw_decode raise JSONDecodeError(\"Expecting value\", s, err.value) from None json.decoder.JSONDecodeError: Expecting value: line 3 column 3 (char 15)\n\n(py3) C:\\Users\\Yusuke>jupyter notebook [W 19:57:34.081 NotebookApp] Collisions detected in C:\\Users\\Yusuke\\.jupyter\\jupyter_notebook_config.py and C:\\Users\\Yusuke\\.jupyter\\jupyter_notebook_config.json config files. C:\\Users\\Yusuke\\.jupyter\\jupyter_notebook_config.json has higher priority: { \"NotebookApp\": { \"kernel_spec_manager_class\": \"'environment_kernels.EnvironmentKernelSpecManager' ignored, using 'nb_conda_kernels.CondaKernelSpecManager'\" } } [I 19:57:36.349 NotebookApp] Removing existing kernelspec in C:\\Users\\Yusuke\\AppData\\Roaming\\jupyter\\kernels\\conda-root-py [I 19:57:36.417 NotebookApp] Installed kernelspec conda-root-py in C:\\Users\\Yusuke\\AppData\\Roaming\\jupyter\\kernels\\conda-root-py [I 19:57:36.424 NotebookApp] Removing existing kernelspec in C:\\Users\\Yusuke\\AppData\\Roaming\\jupyter\\kernels\\conda-env-py3-py [I 19:57:36.471 NotebookApp] Installed kernelspec conda-env-py3-py in C:\\Users\\Yusuke\\AppData\\Roaming\\jupyter\\kernels\\conda-env-py3-py [I 19:57:36.483 NotebookApp] Removing existing kernelspec in C:\\Users\\Yusuke\\AppData\\Roaming\\jupyter\\kernels\\conda-env-py36_test-py [I 19:57:36.515 NotebookApp] Installed kernelspec conda-env-py36_test-py in C:\\Users\\Yusuke\\AppData\\Roaming\\jupyter\\kernels\\conda-env-py36_test-py [I 19:57:36.521 NotebookApp] [nb_conda_kernels] enabled, 3 kernels found [W 2021-06-21 19:57:38.673 LabApp] Config option `kernel_spec_manager_class` not recognized by `LabApp`. [W 2021-06-21 19:57:38.683 LabApp] 'kernel_spec_manager_class' has moved from NotebookApp to ServerApp. This config will be passed to ServerApp. Be sure to update your config before our next release. [W 2021-06-21 19:57:38.683 LabApp] 'kernel_spec_manager_class' has moved from NotebookApp to ServerApp. This config will be passed to ServerApp. Be sure to update your config before our next release. [W 2021-06-21 19:57:38.686 LabApp] Config option `kernel_spec_manager_class` not recognized by `LabApp`. [I 2021-06-21 19:57:38.699 LabApp] JupyterLab extension loaded from C:\\Users\\Yusuke\\Anaconda3\\envs\\py3\\lib\\site-packages\\jupyterlab [I 2021-06-21 19:57:38.699 LabApp] JupyterLab application directory is C:\\Users\\Yusuke\\Anaconda3\\envs\\py3\\share\\jupyter\\lab [I 19:57:38.718 NotebookApp] [nb_conda] enabled [I 19:57:38.726 NotebookApp] Serving notebooks from local directory: C:\\Users\\Yusuke [I 19:57:38.726 NotebookApp] Jupyter Notebook 6.2.0 is running at: [I 19:57:38.728 NotebookApp] http://localhost:8888/?token=557b6bcb4da2b72a866aa0818a902769b2eb241515203de9 [I 19:57:38.729 NotebookApp] or http://127.0.0.1:8888/?token=557b6bcb4da2b72a866aa0818a902769b2eb241515203de9 [I 19:57:38.730 NotebookApp] Use Control-C to stop this server and shut down all kernels (twice to skip confirmation). [C 19:57:38.841 NotebookApp] To access the notebook, open this file in a browser: file:///C:/Users/Yusuke/AppData/Roaming/jupyter/runtime/nbserver-9228-open.html Or copy and paste one of these URLs: http://localhost:8888/?token=557b6bcb4da2b72a866aa0818a902769b2eb241515203de9 or http://127.0.0.1:8888/?token=557b6bcb4da2b72a866aa0818a902769b2eb241515203de9 [E 19:57:42.988 NotebookApp] Uncaught exception GET /conda/environments?_=1624273061120 (::1) HTTPServerRequest(protocol='http', host='localhost:8888', method='GET', uri='/conda/environments?_=1624273061120', version='HTTP/1.1', remote_ip='::1') Traceback (most recent call last): File \"C:\\Users\\Yusuke\\Anaconda3\\envs\\py3\\lib\\site-packages\\tornado\\web.py\", line 1702, in _execute result = method(*self.path_args, **self.path_kwargs) File \"C:\\Users\\Yusuke\\Anaconda3\\envs\\py3\\lib\\site-packages\\tornado\\web.py\", line 3173, in wrapper return method(self, *args, **kwargs) File \"C:\\Users\\Yusuke\\Anaconda3\\envs\\py3\\lib\\site-packages\\notebook\\base\\handlers.py\", line 782, in wrapper return method(self, *args, **kwargs) File \"C:\\Users\\Yusuke\\Anaconda3\\envs\\py3\\lib\\site-packages\\nb_conda\\handlers.py\", line 51, in get self.finish(json.dumps(self.env_manager.list_envs())) File \"C:\\Users\\Yusuke\\Anaconda3\\envs\\py3\\lib\\site-packages\\nb_conda\\envmanager.py\", line 67, in list_envs info = self.clean_conda_json(self._execute('conda info --json')) File \"C:\\Users\\Yusuke\\Anaconda3\\envs\\py3\\lib\\site-packages\\nb_conda\\envmanager.py\", line 53, in _execute output = check_output(cmdline) File \"C:\\Users\\Yusuke\\Anaconda3\\envs\\py3\\lib\\subprocess.py\", line 411, in check_output **kwargs).stdout File \"C:\\Users\\Yusuke\\Anaconda3\\envs\\py3\\lib\\subprocess.py\", line 488, in run with Popen(*popenargs, **kwargs) as process: File \"C:\\Users\\Yusuke\\Anaconda3\\envs\\py3\\lib\\subprocess.py\", line 800, in __init__ restore_signals, start_new_session) File \"C:\\Users\\Yusuke\\Anaconda3\\envs\\py3\\lib\\subprocess.py\", line 1207, in _execute_child startupinfo) FileNotFoundError: [WinError 2] 指定されたファイルが見つかりません。 (The system cannot find the file specified.) [W 19:57:43.110 NotebookApp] Unhandled error E 19:57:43.117 NotebookApp] { \" Host\": \"localhost:8888\", \" Connection\": \"keep-alive\", \"Sec-Ch-Ua\": \"\\\" Not;A Brand\\\";v=\\\"99\\\", \\\"Google Chrome\\\";v=\\\"91\\\", \\\"Chromium\\\";v=\\\"91\\\"\", \"Accept\": \"application/json, text/javascript, */*; q=0.01\", \"X-Xsrftoken\": \"2|31626b86|4b9b22e809faaf9c202ef0efb066520e|1621811786\", \"X-Requested-With\": \"XMLHttpRequest\", \"Sec-Ch-Ua-Mobile\": \"?0\", \"User-Agent\": \"Mozilla/5.0 (Windows NT 10.0; Win64; x64) AppleWebKit/537.36 (KHTML, like Gecko) Chrome/91.0.4472.106 Safari/537.36\", \"Sec-Fetch-Site\": \"same-origin\", \"Sec-Fetch-Mode\": \"cors\", \"Sec-Fetch-Dest\": \"empty\", \"Referer\": \"http://localhost:8888/tree\", \"Accept-Encoding\": \"gzip, deflate, br\", \"Accept-Language\": \"ja,en;q=0.9,en-US;q=0.8\", \"Cookie\": \"_xsrf=2|31626b86|4b9b22e809faaf9c202ef0efb066520e|1621811786; username-localhost-8888=\\\"2|1:0|10:1624273060|23:username-localhost-8888|44:MTc5YzJkMTJhY2ExNDk0ZDhmZWRlZDgyNGVlMTlkYTI=|8e387ac882126f4cc64b15f191a59358762f02ee2e7d18bfe897504bdc6d4efc\\\"\" } [E 19:57:43.117 NotebookApp] 500 GET /conda/environments?_=1624273061120 (::1) 163.420000ms referer=http://localhost:8888/tree [E 19:57:43.140 NotebookApp] Uncaught exception GET /conda/packages/available?_=1624273061121 (::1) HTTPServerRequest(protocol='http', host='localhost:8888', method='GET', uri='/conda/packages/available?_=1624273061121', version='HTTP/1.1', remote_ip='::1') Traceback (most recent call last): File \"C:\\Users\\Yusuke\\Anaconda3\\envs\\py3\\lib\\site-packages\\tornado\\web.py\", line 1702, in _execute result = method(*self.path_args, **self.path_kwargs) File \"C:\\Users\\Yusuke\\Anaconda3\\envs\\py3\\lib\\site-packages\\tornado\\web.py\", line 3173, in wrapper return method(self, *args, **kwargs) File \"C:\\Users\\Yusuke\\Anaconda3\\envs\\py3\\lib\\site-packages\\notebook\\base\\handlers.py\", line 782, in wrapper return method(self, *args, **kwargs) File \"C:\\Users\\Yusuke\\Anaconda3\\envs\\py3\\lib\\site-packages\\nb_conda\\handlers.py\", line 230, in get data = searcher.list_available(self) File \"C:\\Users\\Yusuke\\Anaconda3\\envs\\py3\\lib\\site-packages\\nb_conda\\handlers.py\", line 213, in list_available bufsize=4096) File \"C:\\Users\\Yusuke\\Anaconda3\\envs\\py3\\lib\\subprocess.py\", line 800, in __init__ restore_signals, start_new_session) File \"C:\\Users\\Yusuke\\Anaconda3\\envs\\py3\\lib\\subprocess.py\", line 1207, in _execute_child startupinfo) FileNotFoundError: [WinError 2] 指定されたファイルが見つかりません。(The system cannot find the file specified.) [W 19:57:43.152 NotebookApp] Unhandled error [E 19:57:43.155 NotebookApp] { \"Host\": \"localhost:8888\", \"Connection\": \"keep-alive\", \"Sec-Ch-Ua\": \"\\\" Not;A Brand\\\";v=\\\"99\\\", \\\"Google Chrome\\\";v=\\\"91\\\", \\\"Chromium\\\";v=\\\"91\\\"\", \"Accept\": \"application/json, text/javascript, */*; q=0.01\", \"X-Xsrftoken\": \"2|31626b86|4b9b22e809faaf9c202ef0efb066520e|1621811786\", \"X-Requested-With\": \"XMLHttpRequest\", \"Sec-Ch-Ua-Mobile\": \"?0\", \"User-Agent\": \"Mozilla/5.0 (Windows NT 10.0; Win64; x64) AppleWebKit/537.36 (KHTML, like Gecko) Chrome/91.0.4472.106 Safari/537.36\", \"Sec-Fetch-Site\": \"same-origin\", \"Sec-Fetch-Mode\": \"cors\", \"Sec-Fetch-Dest\": \"empty\", \"Referer\": \"http://localhost:8888/tree\", \"Accept-Encoding\": \"gzip, deflate, br\", \"Accept-Language\": \"ja,en;q=0.9,en-US;q=0.8\", \"Cookie\": \"_xsrf=2|31626b86|4b9b22e809faaf9c202ef0efb066520e|1621811786; username-localhost-8888=\\\"2|1:0|10:1624273060|23:username-localhost-8888|44:MTc5YzJkMTJhY2ExNDk0ZDhmZWRlZDgyNGVlMTlkYTI=|8e387ac882126f4cc64b15f191a59358762f02ee2e7d18bfe897504bdc6d4efc\\\"\" } [E 19:57:43.155 NotebookApp] 500 GET /conda/packages/available?_=1624273061121 (::1) 31.960000ms referer=http://localhost:8888/tree"
    }
}